Workbook

Sheet Opening Balance FEB 2026
D3: Opening Credit Month Of FEB 2026 | H3: Opening Cash Month Of OCT 2025
B4: EXTRA SALE PASS | C4: Same Day Posting | D4: COMPANY | E4: ODERBOOKERS | F4: CREDIT AMOUNT | G4: ACTUAL CREDIT Closed | H4: OPENING CASH | J4: =1308640 -> 1308640
B5: 0 | C5: 0 | D5: CBL | E5: Danish | F5: 391828 | G5: =F5+C5+B5 -> 391828
B6: 0 | C6: 345149 | D6: CBL | E6: Danish ws | F6: =3301295-C6 -> 2956146 | G6: =F6+B6+C6 -> 3301295
B7: 0 | C7: 114280 | D7: CBL | E7: Murtaza | F7: =1178838-C7 -> 1064558 | G7: =F7+C7+B7 -> 1178838
B8: 0 | C8: 223828 | D8: CBL | E8: Ali | F8: =951862-C8 -> 728034 | G8: =F8+B8 -> 728034
B9: 0 | C9: 113776 | D9: CBL | E9: Kashif | F9: =1089429-C9 -> 975653 | G9: =F9+B9 -> 975653
B10: 0 | C10: 145647 | D10: CBL | E10: Anas | F10: =625654-C10 -> 480007 | G10: =F10+C10+B10 -> 625654
B11: =SUM(B5:B10) -> 0 | C11: =SUM(C5:C10) -> 942680 | D11: TOTAL | F11: =SUM(F5:F10) -> 6596226 | G11: =SUM(G5:G10) -> 7201302
D12: COMPANY | E12: ODERBOOKERS | F12: CREDIT AMOUNT
D13: CDM | E13: Qadeer | F13: 282651
D14: CDM | E14: Shahid | F14: =1508814-20000 -> 1488814
D15: CDM | E15: Danish | F15: 612306
D16: CDM | E16: Kashif | F16: 8160
D17: POP NOSH | E17: Shahid | F17: 51257
D18: TOTAL | F18: =SUM(F13:F17) -> 2443188
B19: Extra Bill | C19: Same Day Posting | D19: COMPANY | E19: ODERBOOKERS | F19: CREDIT AMOUNT
C20: 167308 | D20: SHAN FOODs | E20: Khawar | F20: =1560888-C20 -> 1393580
D21: SHAN FOODs | E21: Murtaza | F21: 174473
D22: SHAN FOODs | E22: Danish | F22: 35126
C23: 26216 | D23: SHAN FOODs | E23: Ashraf | F23: =1479667-C23 -> 1453451
D24: SHAN FOODs | E24: Kashif | F24: =96296-30250 -> 66046
C25: 0 | D25: SHAN FOODs | E25: Shahid | F25: 23570
C26: =SUM(C20:C25) -> 193524 | D26: TOTAL | F26: =SUM(F20:F25) -> 3146246
D27: COMPANY | E27: ODERBOOKERS | F27: CREDIT AMOUNT
D28: IMPORTED ITEMS | E28: Shahzad Ahmad | F28: 33969
D29: IMPORTED ITEMS | E29: Shahid | F29: 160846
D30: TOTAL | F30: =SUM(F28:F29) -> 194815
D31: COMPANY | E31: ODERBOOKERS | F31: CREDIT AMOUNT
D32: MAHEE | E32: Shahzad Ahmad | F32: 89658
D33: MAHEE | E33: Murtaza | F33: =67000-25000 -> 42000
D34: TOTAL | F34: =SUM(F32:F33) -> 131658
D35: COMPANY | E35: ODERBOOKERS | F35: CREDIT AMOUNT
D36: PAKAGES | E36: Rabnawaz | F36: 103541
D37: PAKAGES | E37: Shahid | F37: 6013
D38: TOTAL | F38: 109554
D39: COMPANY | E39: ODERBOOKERS | F39: CREDIT AMOUNT
D40: QUICE | E40: Shahid | F40: 16440
D41: TOTAL | F41: 16440
D43: Grand Total | F43: =F41+F38+F34+F30+F26+F18+F11+C11+B11 -> 13580807

Sheet 01-03-2026
C2: 46082
C3: Daily Cash Flow Statement
C4: Companies | D4: Order Bookers | E4: Suppliers | F4: Today Supply | G4: Return Stock | H4: Posting | I4: Credit Posted | J4: Summary Cash | K4: Claim Cleard By Suppliers | L4: Sabqa Payment By Suppliers | M4: Recovery List | N4: Return Stock/Claim Clear By OB | O4: Total Recovery
C5: CBL | D5: Danish | E5: - | F5: 0 | G5: 0 | H5: =F5-G5 -> 0 | I5: =H5-J5 -> 0 | J5: 0 | K5: 0 | L5: 0 | M5: ='Opening Balance FEB 2026'!F5 -> 391828 | N5: 0 | O5: 32313
C6: CBL | D6: Danish ws | E6: Ayoub | F6: 345159 | G6: 0 | H6: =F6-G6 -> 345159 | I6: =H6-J6 -> 345159 | J6: 0 | K6: 0 | L6: 0 | M6: ='Opening Balance FEB 2026'!F6 -> 2956146 | N6: 0 | O6: 0
C7: CBL | D7: Murtaza | E7: PENDING | F7: 114280 | G7: 0 | H7: 0 | I7: =H7-J7 -> 0 | J7: 0 | K7: 0 | L7: 0 | M7: ='Opening Balance FEB 2026'!F7 -> 1064558 | N7: 0 | O7: 51202
C8: CBL | D8: Ali | E8: Ayoub | F8: 223828 | G8: 0 | H8: =F8-G8 -> 223828 | I8: =H8-J8 -> 210838 | J8: 12990 | K8: 0 | L8: 0 | M8: ='Opening Balance FEB 2026'!F8 -> 728034 | N8: 0 | O8: 104161
C9: CBL | D9: Kashif | E9: Aqib/Faiz | F9: 113776 | G9: 0 | H9: =F9-G9 -> 113776 | I9: =H9-J9 -> 102042 | J9: 11734 | K9: 0 | L9: 0 | M9: ='Opening Balance FEB 2026'!F9 -> 975653 | N9: 0 | O9: 19509
C10: CBL | D10: Anas | E10: Aqib/Faiz | F10: 145647 | G10: 0 | H10: =F10-G10 -> 145647 | I10: =H10-J10 -> 15723 | J10: 129924 | K10: 0 | L10: 0 | M10: ='Opening Balance FEB 2026'!F10 -> 480007 | N10: 0 | O10: 25614
C11: Total | F11: =SUM(F5:F10) -> 942690 | G11: =SUM(G5:G10) -> 0 | H11: =SUM(H5:H10) -> 828410 | I11: =SUM(I5:I10) -> 673762 | J11: =SUM(J5:J10) -> 154648 | K11: =SUM(K5:K10) -> 0 | L11: =SUM(L5:L10) -> 0 | M11: =SUM(M5:M10) -> 6596226 | ... O11: =SUM(O5:O10) -> 232799
C12: CDM/TANG | D12: QADEER | E12: Ikram | F12: 74060 | G12: 2871 | H12: =F12-G12 -> 71189 | I12: =H12-J12 -> 28714 | J12: 42475 | K12: 0 | L12: 0 | M12: ='Opening Balance FEB 2026'!F13 -> 282651 | N12: 8688 | O12: 63769
C13: CDM/TANG | D13: QADEER | E13: Aqib/Faiz | F13: 8876 | G13: 0 | H13: =F13-G13 -> 8876 | I13: =H13-J13 -> 0 | J13: 8876 | K13: 0 | L13: 0 | M13: 0 | N13: 0 | O13: 0
C14: CDM/TANG | D14: SHAHID | E14: Ikram | F14: 138156 | G14: 16452 | H14: =F14-G14 -> 121704 | I14: =H14-J14 -> 43497 | J14: 78207 | K14: 332 | L14: 5132 | M14: ='Opening Balance FEB 2026'!F14 -> 1488814 | N14: 0 | O14: 64272
C15: CDM/TANG | D15: DANISH | E15: Counter Sale | F15: 5358 | G15: 0 | H15: =F15-G15 -> 5358 | I15: =H15-J15 -> 0 | J15: 5358 | K15: 0 | L15: 0 | M15: ='Opening Balance FEB 2026'!F15 -> 612306 | N15: 0 | O15: 70602
C16: CDM/TANG | D16: Kashif | E16: Aqib/Faiz | F16: 22065 | G16: 0 | H16: =F16-G16 -> 22065 | I16: =H16-J16 -> 0 | J16: 22065 | K16: 0 | L16: 0 | M16: ='Opening Balance FEB 2026'!F16 -> 8160 | N16: 0 | O16: 0
C17: CDM/TANG | D17: Murtaza | E17: - | F17: 0 | G17: 0 | H17: =F17-G17 -> 0 | I17: =H17-J17 -> 0 | J17: 0 | K17: 0 | L17: 0 | M17: 0 | N17: 0 | O17: 0
C18: CDM/TANG | F18: =SUM(F12:F17) -> 248515 | G18: =SUM(G12:G17) -> 19323 | H18: =SUM(H12:H16) -> 229192 | I18: =SUM(I12:I16) -> 72211 | J18: =SUM(J12:J17) -> 156981 | K18: =SUM(K12:K16) -> 332 | L18: =SUM(L12:L16) -> 5132 | M18: =SUM(M12:M17) -> 2391931 | N18: =SUM(N12:N16) -> 8688 | O18: =SUM(O12:O17) -> 198643
C19: POP NOSH | D19: SHAHID | E19: - | F19: 0 | G19: 0 | H19: =F19-G19 -> 0 | I19: =H19-J19 -> 0 | J19: 0 | K19: 0 | L19: 0 | M19: ='Opening Balance FEB 2026'!F17 -> 51257 | N19: 0 | O19: 0
F20: =SUM(F19) -> 0 | G20: =SUM(G19) -> 0 | H20: =SUM(H19) -> 0 | I20: =SUM(I19) -> 0 | J20: =SUM(J19) -> 0 | K20: =SUM(K19) -> 0 | L20: =SUM(L19) -> 0 | M20: =SUM(M19) -> 51257 | ... O20: =SUM(O19) -> 0
C21: Imported Items | D21: SHAHZAD AHMAD | E21: - | F21: 0 | G21: 0 | H21: =F21-G21 -> 0 | I21: =H21-J21 -> 0 | J21: 0 | K21: 0 | L21: 0 | M21: ='Opening Balance FEB 2026'!F28 -> 33969 | N21: 0 | O21: 0
C22: Imported Items | D22: SHAHID | E22: - | F22: 0 | G22: 0 | H22: =F22-G22 -> 0 | I22: =H22-J22 -> 0 | J22: 0 | K22: 0 | L22: 0 | M22: ='Opening Balance FEB 2026'!F29 -> 160846 | N22: 0 | O22: 0
C23: Total | F23: =SUM(F21:F22) -> 0 | G23: =SUM(G21:G22) -> 0 | H23: =SUM(H21:H22) -> 0 | I23: =SUM(I21:I22) -> 0 | J23: =SUM(J21:J22) -> 0 | K23: =SUM(K21:K22) -> 0 | L23: =SUM(L21:L22) -> 0 | M23: =SUM(M21:M22) -> 194815 | ... O23: =SUM(O21:O22) -> 0
C24: TAHORA | D24: SHAHZAD AHMAD | E24: - | F24: 0 | G24: 0 | H24: =F24-G24 -> 0 | I24: =H24-J24 -> 0 | J24: 0 | K24: 0 | L24: 0 | M24: ='Opening Balance FEB 2026'!F32 -> 89658 | N24: 0 | O24: 0
C25: TAHORA | D25: MURTAZA | E25: - | F25: 0 | G25: 0 | H25: =F25-G25 -> 0 | I25: =H25-J25 -> 0 | J25: 0 | K25: 0 | L25: 0 | M25: ='Opening Balance FEB 2026'!F33 -> 42000 | N25: 0 | O25: 0
C26: Total | F26: =SUM(F24:F25) -> 0 | G26: =SUM(G24:G25) -> 0 | H26: =SUM(H24:H25) -> 0 | I26: =SUM(I24:I25) -> 0 | J26: =SUM(J24:J25) -> 0 | K26: =SUM(K24:K25) -> 0 | L26: =SUM(L24:L25) -> 0 | M26: =SUM(M24:M25) -> 131658 | ... O26: =SUM(O24:O25) -> 0
C27: SHAN | D27: KHAWAR | E27: Sami | F27: 167308 | G27: 0 | H27: =F27-G27 -> 167308 | I27: =H27-J27 -> 167308 | J27: 0 | K27: 0 | L27: 0 | M27: ='Opening Balance FEB 2026'!F20 -> 1393580 | N27: 0 | O27: 69025
C28: SHAN | D28: MURTAZA | E28: - | F28: 0 | G28: 0 | H28: =F28-G28 -> 0 | I28: =H28-J28 -> 0 | J28: 0 | K28: 0 | L28: 0 | M28: ='Opening Balance FEB 2026'!F21 -> 174473 | N28: 0 | O28: 0
C29: SHAN | D29: DANISH | E29: - | F29: 0 | G29: 0 | H29: =F29-G29 -> 0 | I29: =H29-J29 -> 0 | J29: 0 | K29: 0 | L29: 0 | M29: ='Opening Balance FEB 2026'!F22 -> 35126 | N29: 0 | O29: 0
C30: SHAN | D30: ASHRAF | E30: Ikram | F30: 26216 | G30: 0 | H30: =F30-G30 -> 26216 | I30: =H30-J30 -> 24825 | J30: 1391 | K30: 0 | L30: 0 | M30: ='Opening Balance FEB 2026'!F23 -> 1453451 | N30: 2208 | O30: 55906
C31: Total | F31: =SUM(F27:F30) -> 193524 | G31: =SUM(G27:G30) -> 0 | H31: =SUM(H27:H30) -> 193524 | I31: =SUM(I27:I30) -> 192133 | J31: =SUM(J27:J30) -> 1391 | K31: =SUM(K27:K30) -> 0 | L31: =SUM(L27:L30) -> 0 | M31: =SUM(M27:M30) -> 3056630 | ... O31: =SUM(O27:O30) -> 124931
C32: NET TOTAL | F32: =F31+F26+F23+F20+F18+F11 -> 1384729 | G32: =G31+G26+G23+G20+G18+G11 -> 19323 | H32: =H31+H26+H23+H20+H18+H11 -> 1251126 | I32: =I31+I26+I23+I20+I18+I11 -> 938106 | J32: =J31+J26+J23+J20+J18+J11 -> 313020 | K32: =K31+K26+K23+K20+K18+K11 -> 332 | L32: =L31+L26+L23+L20+L18+L11 -> 5132 | M32: =M31+M26+M23+M20+M18+M11 -> 12422517 | ... O32: =O31+O26+O23+O20+O18+O11 -> 556373
F33: CBL Cash | G33: =O11+L11+J11-K11 -> 387447
F34: CDM Cash | G34: =O18+L18+J18-K18+O20+L20+J20-K20 -> 360424 | I34: Amount | J34: MCB Onlines | K34: Value | M34: Detail
C35: Onlines | F35: Imported Item Cash | G35: =O23+L23+J23-K23 -> 0
F36: TAHORA | G36: =O26+L26+J26-K26 -> 0
F37: Shan Food's Cash | G37: =O31+L31+J31-K31 -> 126322
F38: Total Cash | G38: =SUM(G33:G37) -> 874193
H48: Today Credit Closed
H49: COMPANY | I49: ODERBOOKERS | J49: CREDIT AMOUNT
H50: CBL | I50: Danish | J50: =M5-O5-N5-L5+I5 -> 359515 | K50: 359515 | L50: =J50-K50 -> 0
...

Sheet 02-03-2026
C2: 46083
C3: Daily Cash Flow Statement
C4: Companies | D4: Order Bookers | E4: Suppliers | F4: Today Supply | G4: Return Stock | H4: Posting | I4: Credit Posted | J4: Summary Cash | K4: Claim Cleard By Suppliers | L4: Sabqa Payment By Suppliers | M4: Recovery List | N4: Return Stock/Claim Clear By OB | O4: Total Recovery
C5: CBL | D5: Danish | E5: Aqib/Faiz | F5: 90007 | G5: 2634 | H5: =F5-G5 -> 87373 | I5: =H5-J5 -> 34506 | J5: 52867 | K5: 0 | L5: 0 | M5: ='01-03-2026'!J50 -> 359515 | N5: 0 | O5: 41122
C6: CBL | D6: Danish ws | E6: - | F6: 0 | G6: 0 | H6: =F6-G6 -> 0 | I6: =H6-J6 -> 0 | J6: 0 | K6: 0 | L6: 0 | M6: ='01-03-2026'!J51 -> 3301305 | N6: 0 | O6: 0
C7: CBL | D7: Murtaza | E7: Ayoub | F7: 114280 | G7: 1408 | H7: =F7-G7 -> 112872 | I7: =H7-J7 -> 107869 | J7: 5003 | K7: 0 | L7: 0 | M7: ='01-03-2026'!J52 -> 1013356 | N7: 0 | O7: 40570
C8: CBL | D8: Murtaza | E8: Awais | F8: 70251 | G8: 0 | H8: =F8-G8 -> 70251 | I8: =H8-J8 -> 65442 | J8: 4809 | K8: 0 | L8: 0 | M8: 0 | N8: 0 | O8: 0
C9: CBL | D9: Ali | E9: Awais | F9: 51794 | G9: 0 | H9: =F9-G9 -> 51794 | I9: =H9-J9 -> 36510 | J9: 15284 | K9: 0 | L9: 0 | M9: ='01-03-2026'!J53 -> 834711 | N9: 0 | O9: 44129
C10: CBL | D10: Kashif | E10: Aqib/Faiz | F10: 95030 | G10: 5166 | H10: =F10-G10 -> 89864 | I10: =H10-J10 -> 79373 | J10: 10491 | K10: 0 | L10: 0 | M10: ='01-03-2026'!J54 -> 1058186 | N10: 0 | O10: 28373
C11: CBL | D11: Anas | E11: Ayoub | F11: 35055 | G11: 0 | H11: =F11-G11 -> 35055 | I11: =H11-J11 -> 26929 | J11: 8126 | K11: 0 | L11: 0 | M11: ='01-03-2026'!J55 -> 470116 | N11: 0 | O11: 42946
C12: Total | F12: =SUM(F5:F11) -> 456417 | G12: =SUM(G5:G11) -> 9208 | H12: =SUM(H5:H11) -> 447209 | I12: =SUM(I5:I11) -> 350629 | J12: =SUM(J5:J11) -> 96580 | K12: =SUM(K5:K11) -> 0 | L12: =SUM(L5:L11) -> 0 | M12: =SUM(M5:M11) -> 7037189 | ... O12: =SUM(O5:O11) -> 197140
C13: CDM/TANG | D13: QADEER | E13: Ikram | F13: 255556 | G13: 2613 | H13: =F13-G13 -> 252943 | I13: =H13-J13 -> 230037 | J13: 22906 | K13: 0 | L13: 0 | M13: ='01-03-2026'!J59 -> 238908 | N13: 0 | O13: 33057
C14: CDM/TANG | D14: SHAHID | E14: Ikram | F14: 59685 | G14: 0 | H14: =F14-G14 -> 59685 | I14: =H14-J14 -> 51512 | J14: 8173 | K14: 0 | L14: 15651 | M14: ='01-03-2026'!J60 -> 1462907 | N14: 0 | O14: 0
C15: CDM/TANG | D15: SHAHID | E15: Aqib/Faiz | F15: 78329 | G15: 7272 | H15: =F15-G15 -> 71057 | I15: =H15-J15 -> 0 | J15: 71057 | K15: 0 | L15: 0 | M15: 0 | N15: 0 | O15: 0
C16: CDM/TANG | D16: DANISH | E16: Sami | F16: 123347 | G16: 0 | H16: =F16-G16 -> 123347 | I16: =H16-J16 -> 95985 | J16: 27362 | K16: 0 | L16: 0 | M16: ='01-03-2026'!J61 -> 541704 | N16: 0 | O16: 20000
C17: CDM/TANG | D17: DANISH | E17: Aqib/Faiz | F17: 10316 | G17: 0 | H17: =F17-G17 -> 10316 | I17: =H17-J17 -> 0 | J17: 10316 | K17: 0 | L17: 0 | M17: 0 | N17: 0 | O17: 0
C18: CDM/TANG | D18: Kashif | E18: Aqib/Faiz | F18: 9753 | G18: 0 | H18: =F18-G18 -> 9753 | I18: =H18-J18 -> 0 | J18: 9753 | K18: 0 | L18: 0 | M18: ='01-03-2026'!J62 -> 8160 | N18: 0 | O18: 0
C19: CDM/TANG | D19: Murtaza | E19: - | F19: 0 | G19: 0 | H19: =F19-G19 -> 0 | I19: =H19-J19 -> 0 | J19: 0 | K19: 0 | L19: 0 | M19: 0 | N19: 0 | O19: 0
C20: CDM/TANG | F20: =SUM(F13:F19) -> 536986 | G20: =SUM(G13:G19) -> 9885 | H20: =SUM(H13:H18) -> 527101 | I20: =SUM(I13:I18) -> 377534 | J20: =SUM(J13:J19) -> 149567 | K20: =SUM(K13:K18) -> 0 | L20: =SUM(L13:L18) -> 15651 | M20: =SUM(M13:M19) -> 2251679 | N20: =SUM(N13:N18) -> 0 | O20: =SUM(O13:O19) -> 53057
C21: POP NOSH | D21: SHAHID | E21: - | F21: 0 | G21: 0 | H21: =F21-G21 -> 0 | I21: =H21-J21 -> 0 | J21: 0 | K21: 0 | L21: 0 | M21: ='01-03-2026'!J63 -> 51257 | N21: 0 | O21: 0
F22: =SUM(F21) -> 0 | G22: =SUM(G21) -> 0 | H22: =SUM(H21) -> 0 | I22: =SUM(I21) -> 0 | J22: =SUM(J21) -> 0 | K22: =SUM(K21) -> 0 | L22: =SUM(L21) -> 0 | M22: =SUM(M21) -> 51257 | ... O22: =SUM(O21) -> 0
C23: Imported Items | D23: SHAHZAD AHMAD | E23: - | F23: 0 | G23: 0 | H23: =F23-G23 -> 0 | I23: =H23-J23 -> 0 | J23: 0 | K23: 0 | L23: 0 | M23: ='01-03-2026'!J74 -> 33969 | N23: 0 | O23: 0
C24: Imported Items | D24: SHAHID | E24: - | F24: 0 | G24: 0 | H24: =F24-G24 -> 0 | I24: =H24-J24 -> 0 | J24: 0 | K24: 0 | L24: 0 | M24: ='01-03-2026'!J75 -> 160846 | N24: 0 | O24: 0
C25: Total | F25: =SUM(F23:F24) -> 0 | G25: =SUM(G23:G24) -> 0 | H25: =SUM(H23:H24) -> 0 | I25: =SUM(I23:I24) -> 0 | J25: =SUM(J23:J24) -> 0 | K25: =SUM(K23:K24) -> 0 | L25: =SUM(L23:L24) -> 0 | M25: =SUM(M23:M24) -> 194815 | ... O25: =SUM(O23:O24) -> 0
C26: TAHORA | D26: SHAHZAD AHMAD | E26: - | F26: 0 | G26: 0 | H26: =F26-G26 -> 0 | I26: =H26-J26 -> 0 | J26: 0 | K26: 0 | L26: 0 | M26: ='01-03-2026'!J78 -> 89658 | N26: 0 | O26: 0
C27: TAHORA | D27: MURTAZA | E27: - | F27: 0 | G27: 0 | H27: =F27-G27 -> 0 | I27: =H27-J27 -> 0 | J27: 0 | K27: 0 | L27: 0 | M27: ='01-03-2026'!J79 -> 42000 | N27: 0 | O27: 0
C28: Total | F28: =SUM(F26:F27) -> 0 | G28: =SUM(G26:G27) -> 0 | H28: =SUM(H26:H27) -> 0 | I28: =SUM(I26:I27) -> 0 | J28: =SUM(J26:J27) -> 0 | K28: =SUM(K26:K27) -> 0 | L28: =SUM(L26:L27) -> 0 | M28: =SUM(M26:M27) -> 131658 | ... O28: =SUM(O26:O27) -> 0
C29: SHAN | D29: KHAWAR | E29: Aqib/Faiz | F29: 27736 | G29: 2839 | H29: =F29-G29 -> 24897 | I29: =H29-J29 -> 22417 | J29: 2480 | K29: 0 | L29: 0 | M29: ='01-03-2026'!J66 -> 1491863 | N29: 0 | O29: 69021
C30: SHAN | D30: MURTAZA | E30: - | F30: 0 | G30: 0 | H30: =F30-G30 -> 0 | I30: =H30-J30 -> 0 | J30: 0 | K30: 0 | L30: 0 | M30: ='01-03-2026'!J67 -> 174473 | N30: 0 | O30: 0
C31: SHAN | D31: DANISH | E31: - | F31: 0 | G31: 0 | H31: =F31-G31 -> 0 | I31: =H31-J31 -> 0 | J31: 0 | K31: 0 | L31: 0 | M31: ='01-03-2026'!J68 -> 35126 | N31: 0 | O31: 0
C32: SHAN | D32: ASHRAF | E32: Ayoub | F32: 36887 | G32: 0 | H32: =F32-G32 -> 36887 | I32: =H32-J32 -> 33406 | J32: 3481 | K32: 0 | L32: 0 | M32: ='01-03-2026'!J69 -> 1420162 | N32: 0 | O32: 43440
C33: Total | F33: =SUM(F29:F32) -> 64623 | G33: =SUM(G29:G32) -> 2839 | H33: =SUM(H29:H32) -> 61784 | I33: =SUM(I29:I32) -> 55823 | J33: =SUM(J29:J32) -> 5961 | K33: =SUM(K29:K32) -> 0 | L33: =SUM(L29:L32) -> 0 | M33: =SUM(M29:M32) -> 3121624 | ... O33: =SUM(O29:O32) -> 112461
C34: NET TOTAL | F34: =F33+F28+F25+F22+F20+F12 -> 1058026 | G34: =G33+G28+G25+G22+G20+G12 -> 21932 | H34: =H33+H28+H25+H22+H20+H12 -> 1036094 | I34: =I33+I28+I25+I22+I20+I12 -> 783986 | J34: =J33+J28+J25+J22+J20+J12 -> 252108 | K34: =K33+K28+K25+K22+K20+K12 -> 0 | L34: =L33+L28+L25+L22+L20+L12 -> 15651 | M34: =M33+M28+M25+M22+M20+M12 -> 12788222 | ... O34: =O33+O28+O25+O22+O20+O12 -> 362658
F35: CBL Cash | G35: =O12+L12+J12-K12 -> 293720
F36: CDM Cash | G36: =O20+L20+J20-K20+O22+L22+J22-K22 -> 218275 | I36: Amount | J36: MCB Onlines | K36: Value | M36: Detail
C37: Onlines | F37: Imported Item Cash | G37: =O25+L25+J25-K25 -> 0
F38: TAHORA | G38: =O28+L28+J28-K28 -> 0
F39: Shan Food's Cash | G39: =O33+L33+J33-K33 -> 118422
F40: Total Cash | G40: =SUM(G35:G39) -> 630417
H50: Today Credit Closed
...

Sheet 03-03-2026
C2: 46084
C3: Daily Cash Flow Statement
C4: Companies | D4: Order Bookers | E4: Suppliers | F4: Today Supply | G4: Return Stock | H4: Posting | I4: Credit Posted | J4: Summary Cash | K4: Claim Cleard By Suppliers | L4: Sabqa Payment By Suppliers | M4: Recovery List | N4: Return Stock/Claim Clear By OB | O4: Total Recovery
C5: CBL | D5: Danish | E5: Aqib/Faiz | F5: 67808 | G5: 2054 | H5: =F5-G5 -> 65754 | I5: =H5-J5 -> 23341 | J5: 42413 | K5: 1624 | L5: 5000 | M5: ='02-03-2026'!J52 -> 352899 | N5: 0 | O5: 39440
C6: CBL | D6: Danish | E6: Ikram/Saad | F6: 41683 | G6: 3220 | H6: =F6-G6 -> 38463 | I6: =H6-J6 -> 25650 | J6: 12813 | K6: 0 | L6: 10000 | M6: 0 | N6: 0 | O6: 0
C7: CBL | D7: Danish ws | E7: - | F7: 0 | G7: 0 | H7: =F7-G7 -> 0 | I7: =H7-J7 -> 0 | J7: 0 | K7: 0 | L7: 0 | M7: ='02-03-2026'!J53 -> 3301305 | N7: 0 | O7: 195000
C8: CBL | D8: Murtaza | E8: Aqib/Faiz | F8: 100132 | G8: 1387 | H8: =F8-G8 -> 98745 | I8: =H8-J8 -> 50137 | J8: 48608 | K8: 0 | L8: 0 | M8: ='02-03-2026'!J54 -> 1146097 | N8: 0 | O8: 70596
C9: CBL | D9: Ali | E9: Ayoub | F9: 68081 | G9: 1870 | H9: =F9-G9 -> 66211 | I9: =H9-J9 -> 59729 | J9: 6482 | K9: 0 | L9: 0 | M9: ='02-03-2026'!J55 -> 827092 | N9: 0 | O9: 91603
C10: CBL | D10: Kashif | E10: Awais | F10: 105084 | G10: 0 | H10: =F10-G10 -> 105084 | I10: =H10-J10 -> 65489 | J10: 39595 | K10: 265 | L10: 1000 | M10: ='02-03-2026'!J56 -> 1109186 | N10: 0 | O10: 27349
C11: CBL | D11: Anas | E11: Ikram/Saad | F11: 47680 | G11: 1099 | H11: =F11-G11 -> 46581 | I11: =H11-J11 -> 29601 | J11: 16980 | K11: 0 | L11: 0 | M11: ='02-03-2026'!J57 -> 454099 | N11: 0 | O11: 31775
C12: Total | F12: =SUM(F5:F11) -> 430468 | G12: =SUM(G5:G11) -> 9630 | H12: =SUM(H5:H11) -> 420838 | I12: =SUM(I5:I11) -> 253947 | J12: =SUM(J5:J11) -> 166891 | K12: =SUM(K5:K11) -> 1889 | L12: =SUM(L5:L11) -> 16000 | M12: =SUM(M5:M11) -> 7190678 | ... O12: =SUM(O5:O11) -> 455763
C13: CDM/TANG | D13: QADEER | E13: Sami | F13: 114159 | G13: 10159 | H13: =F13-G13 -> 104000 | I13: =H13-J13 -> 38492 | J13: 65508 | K13: 305 | L13: 0 | M13: ='02-03-2026'!J61 -> 435888 | N13: 0 | O13: 13413
C14: CDM/TANG | D14: SHAHID | E14: Awais | F14: 115818 | G14: 0 | H14: =F14-G14 -> 115818 | I14: =H14-J14 -> 34766 | J14: 81052 | K14: 0 | L14: 0 | M14: ='02-03-2026'!J62 -> 1498768 | N14: 0 | O14: 330163
C15: CDM/TANG | D15: SHAHID | E15: Ikram/Saad | F15: 21116 | G15: 1395 | H15: =F15-G15 -> 19721 | I15: =H15-J15 -> 0 | J15: 19721 | K15: 0 | L15: 0 | M15: 0 | N15: 0 | O15: 0
C16: CDM/TANG | D16: SHAHID | E16: Ikram/Saad | F16: 31467 | G16: 0 | H16: =F16-G16 -> 31467 | I16: =H16-J16 -> 0 | J16: 31467 | K16: 0 | L16: 0 | M16: 0 | N16: 0 | O16: 0
C17: CDM/TANG | D17: DANISH | E17: Sami | F17: 0 | G17: 0 | H17: =F17-G17 -> 0 | I17: =H17-J17 -> 0 | J17: 0 | K17: 0 | L17: 0 | M17: ='02-03-2026'!J63 -> 617689 | N17: 0 | O17: 0
C18: CDM/TANG | D18: Kashif | E18: Awais | F18: 0 | G18: 0 | H18: =F18-G18 -> 0 | I18: =H18-J18 -> 0 | J18: 0 | K18: 0 | L18: 0 | M18: 0 | N18: 0 | O18: 0
C19: CDM/TANG | D19: Murtaza | E19: Aqib/Faiz | F19: 30193 | G19: 0 | H19: =F19-G19 -> 30193 | I19: =H19-J19 -> 0 | J19: 30193 | K19: 0 | L19: 0 | M19: 0 | N19: 0 | O19: 0
C20: CDM/TANG | F20: =SUM(F13:F19) -> 312753 | G20: =SUM(G13:G19) -> 11554 | H20: =SUM(H13:H18) -> 271006 | I20: =SUM(I13:I18) -> 73258 | J20: =SUM(J13:J19) -> 227941 | K20: =SUM(K13:K18) -> 305 | L20: =SUM(L13:L18) -> 0 | M20: =SUM(M13:M19) -> 2552345 | N20: =SUM(N13:N18) -> 0 | O20: =SUM(O13:O19) -> 343576
C21: POP NOSH | D21: SHAHID | E21: - | F21: 0 | G21: 0 | H21: =F21-G21 -> 0 | I21: =H21-J21 -> 0 | J21: 0 | K21: 0 | L21: 0 | M21: ='02-03-2026'!J65 -> 51257 | N21: 0 | O21: 0
F22: =SUM(F21) -> 0 | G22: =SUM(G21) -> 0 | H22: =SUM(H21) -> 0 | I22: =SUM(I21) -> 0 | J22: =SUM(J21) -> 0 | K22: =SUM(K21) -> 0 | L22: =SUM(L21) -> 0 | M22: =SUM(M21) -> 51257 | ... O22: =SUM(O21) -> 0
C23: Imported Items | D23: SHAHZAD AHMAD | E23: - | F23: 0 | G23: 0 | H23: =F23-G23 -> 0 | I23: =H23-J23 -> 0 | J23: 0 | K23: 0 | L23: 0 | M23: ='02-03-2026'!J76 -> 33969 | N23: 0 | O23: 0
C24: Imported Items | D24: SHAHID | E24: - | F24: 0 | G24: 0 | H24: =F24-G24 -> 0 | I24: =H24-J24 -> 0 | J24: 0 | K24: 0 | L24: 0 | M24: ='02-03-2026'!J77 -> 160846 | N24: 0 | O24: 0
C25: Total | F25: =SUM(F23:F24) -> 0 | G25: =SUM(G23:G24) -> 0 | H25: =SUM(H23:H24) -> 0 | I25: =SUM(I23:I24) -> 0 | J25: =SUM(J23:J24) -> 0 | K25: =SUM(K23:K24) -> 0 | L25: =SUM(L23:L24) -> 0 | M25: =SUM(M23:M24) -> 194815 | ... O25: =SUM(O23:O24) -> 0
C26: TAHORA | D26: SHAHZAD AHMAD | E26: - | F26: 0 | G26: 0 | H26: =F26-G26 -> 0 | I26: =H26-J26 -> 0 | J26: 0 | K26: 0 | L26: 0 | M26: ='02-03-2026'!J80 -> 89658 | N26: 0 | O26: 0
C27: TAHORA | D27: MURTAZA | E27: - | F27: 0 | G27: 0 | H27: =F27-G27 -> 0 | I27: =H27-J27 -> 0 | J27: 0 | K27: 0 | L27: 0 | M27: ='02-03-2026'!J81 -> 42000 | N27: 0 | O27: 0
C28: Total | F28: =SUM(F26:F27) -> 0 | G28: =SUM(G26:G27) -> 0 | H28: =SUM(H26:H27) -> 0 | I28: =SUM(I26:I27) -> 0 | J28: =SUM(J26:J27) -> 0 | K28: =SUM(K26:K27) -> 0 | L28: =SUM(L26:L27) -> 0 | M28: =SUM(M26:M27) -> 131658 | ... O28: =SUM(O26:O27) -> 0
C29: SHAN | D29: KHAWAR | E29: Aqib/Faiz | F29: 33068 | G29: 0 | H29: =F29-G29 -> 33068 | I29: =H29-J29 -> 33068 | J29: 0 | K29: 0 | L29: 0 | M29: ='02-03-2026'!J68 -> 1445259 | N29: 0 | O29: 18000
C30: SHAN | D30: KHAWAR | E30: Ikram/Saad | F30: 28479 | G30: 1516 | H30: =F30-G30 -> 26963 | I30: =H30-J30 -> 18921 | J30: 8042 | K30: 0 | L30: 0 | M30: 0 | N30: 0 | O30: 0
C31: SHAN | D31: MURTAZA | E31: - | F31: 0 | G31: 0 | H31: =F31-G31 -> 0 | I31: =H31-J31 -> 0 | J31: 0 | K31: 0 | L31: 0 | M31: ='02-03-2026'!J69 -> 174473 | N31: 0 | O31: 0
C32: SHAN | D32: DANISH | E32: - | F32: 0 | G32: 0 | H32: =F32-G32 -> 0 | I32: =H32-J32 -> 0 | J32: 0 | K32: 0 | L32: 0 | M32: ='02-03-2026'!J70 -> 35126 | N32: 0 | O32: 0
C33: SHAN | D33: ASHRAF | E33: Ayoub | F33: 32529 | G33: 0 | H33: =F33-G33 -> 32529 | I33: =H33-J33 -> 32529 | J33: 0 | K33: 0 | L33: 0 | M33: ='02-03-2026'!J71 -> 1410128 | N33: 0 | O33: 71948
C34: Total | F34: =SUM(F29:F33) -> 94076 | G34: =SUM(G29:G33) -> 1516 | H34: =SUM(H29:H33) -> 92560 | I34: =SUM(I29:I33) -> 84518 | J34: =SUM(J29:J33) -> 8042 | K34: =SUM(K29:K33) -> 0 | L34: =SUM(L29:L33) -> 0 | M34: =SUM(M29:M33) -> 3064986 | ... O34: =SUM(O29:O33) -> 89948
C35: NET TOTAL | F35: =F34+F28+F25+F22+F20+F12 -> 837297 | G35: =G34+G28+G25+G22+G20+G12 -> 22700 | H35: =H34+H28+H25+H22+H20+H12 -> 784404 | I35: =I34+I28+I25+I22+I20+I12 -> 411723 | J35: =J34+J28+J25+J22+J20+J12 -> 402874 | K35: =K34+K28+K25+K22+K20+K12 -> 2194 | L35: =L34+L28+L25+L22+L20+L12 -> 16000 | M35: =M34+M28+M25+M22+M20+M12 -> 13185739 | ... O35: =O34+O28+O25+O22+O20+O12 -> 889287
F36: CBL Cash | G36: =O12+L12+J12-K12 -> 636765
F37: CDM Cash | G37: =O20+L20+J20-K20+O22+L22+J22-K22 -> 571212 | I37: Amount | J37: MCB Onlines | K37: Value | M37: Detail
C38: Onlines | F38: Imported Item Cash | G38: =O25+L25+J25-K25 -> 0
F39: TAHORA | G39: =O28+L28+J28-K28 -> 0
F40: Shan Food's Cash | G40: =O34+L34+J34-K34 -> 97990
F41: Total Cash | G41: =SUM(G36:G40) -> 1305967
...

Sheet 04-03-2026
C2: 46085
C3: Daily Cash Flow Statement
C4: Companies | D4: Order Bookers | E4: Suppliers | F4: Today Supply | G4: Return Stock | H4: Posting | I4: Credit Posted | J4: Summary Cash | K4: Claim Cleard By Suppliers | L4: Sabqa Payment By Suppliers | M4: Recovery List | N4: Return Stock/Claim Clear By OB | O4: Total Recovery
C5: CBL | D5: Danish | E5: Aqib/Faiz | F5: 0 | G5: 0 | H5: =F5-G5 -> 0 | I5: =H5-J5 -> 0 | J5: 0 | K5: 0 | L5: 0 | M5: ='03-03-2026'!J53 -> 347450 | N5: 0 | O5: 0
C6: CBL | D6: Danish ws | E6: Ayoub | F6: 455554 | G6: 0 | H6: =F6-G6 -> 455554 | I6: =H6-J6 -> 455554 | J6: 0 | K6: 0 | L6: 0 | M6: ='03-03-2026'!J54 -> 3106305 | N6: 0 | O6: 0
C7: CBL | D7: Murtaza | E7: Awais | F7: 124731 | G7: 0 | H7: =F7-G7 -> 124731 | I7: =H7-J7 -> 103871 | J7: 20860 | K7: 0 | L7: 0 | M7: ='03-03-2026'!J55 -> 1125638 | N7: 0 | O7: 71286
C8: CBL | D8: Ali | E8: Ayoub | F8: 90594 | G8: 0 | H8: =F8-G8 -> 90594 | I8: =H8-J8 -> 83025 | J8: 7569 | K8: 0 | L8: 0 | M8: ='03-03-2026'!J56 -> 795218 | N8: 0 | O8: 42458
C9: CBL | D9: Ali | E9: Awais | F9: 11208 | G9: 0 | H9: =F9-G9 -> 11208 | I9: =H9-J9 -> 11208 | J9: 0
C10: CBL | D10: Kashif | E10: Aqib/Faiz | F10: 151571 | G10: 0 | H10: =F10-G10 -> 151571 | I10: =H10-J10 -> 120820 | J10: 30751 | K10: 0 | L10: 3000 | M10: ='03-03-2026'!J57 -> 1146326 | N10: 0 | O10: 21705
C11: CBL | D11: Anas | E11: Awais | F11: 50371 | G11: 0 | H11: =F11-G11 -> 50371 | I11: =H11-J11 -> 37794 | J11: 12577 | K11: 0 | L11: 797 | M11: ='03-03-2026'!J58 -> 451925 | N11: 0 | O11: 33832
C12: Total | F12: =SUM(F5:F11) -> 884029 | G12: =SUM(G5:G11) -> 0 | H12: =SUM(H5:H11) -> 884029 | I12: =SUM(I5:I11) -> 812272 | J12: =SUM(J5:J11) -> 71757 | K12: =SUM(K5:K11) -> 0 | L12: =SUM(L5:L11) -> 3797 | M12: =SUM(M5:M11) -> 6972862 | ... O12: =SUM(O5:O11) -> 169281
C13: CDM/TANG | D13: QADEER | E13: Aqib/Faiz | F13: 31966 | G13: 0 | H13: =F13-G13 -> 31966 | I13: =H13-J13 -> 17000 | J13: 14966 | K13: 0 | L13: 0 | M13: ='03-03-2026'!J62 -> 460967 | N13: 0 | O13: 22256
C14: CDM/TANG | D14: QADEER | E14: Ikram | F14: 67253 | G14: 1504 | H14: =F14-G14 -> 65749 | I14: =H14-J14 -> 21485 | J14: 44264
C15: CDM/TANG | D15: SHAHID | E15: Ikram | F15: 141207 | G15: 0 | H15: =F15-G15 -> 141207 | I15: =H15-J15 -> 132647 | J15: 8560 | K15: 0 | L15: 0 | M15: ='03-03-2026'!J63 -> 1203371 | N15: 0 | O15: 8422
D16: SHAHID | E16: Ikram | F16: 211870 | G16: 0 | H16: =F16-G16 -> 211870 | I16: =H16-J16 -> 211870 | J16: 0
C17: CDM/TANG | D17: DANISH | E17: Sami | F17: 0 | G17: 0 | H17: =F17-G17 -> 0 | I17: =H17-J17 -> 0 | J17: 0 | K17: 0 | L17: 0 | M17: ='03-03-2026'!J64 -> 617689 | N17: 0 | O17: 0
C18: CDM/TANG | D18: Kashif | E18: Awais | F18: 0 | G18: 0 | H18: =F18-G18 -> 0 | I18: =H18-J18 -> 0 | J18: 0 | K18: 0 | L18: 0 | M18: 0 | N18: 0 | O18: 0
C19: CDM/TANG | D19: Murtaza | E19: Aqib/Faiz | F19: 0 | G19: 0 | H19: =F19-G19 -> 0 | I19: =H19-J19 -> 0 | J19: 0 | K19: 0 | L19: 0 | M19: 0 | N19: 0 | O19: 0
C20: CDM/TANG | F20: =SUM(F13:F19) -> 452296 | G20: =SUM(G13:G19) -> 1504 | H20: =SUM(H13:H18) -> 450792 | I20: =SUM(I13:I18) -> 383002 | J20: =SUM(J13:J19) -> 67790 | K20: =SUM(K13:K18) -> 0 | L20: =SUM(L13:L18) -> 0 | M20: =SUM(M13:M19) -> 2282027 | N20: =SUM(N13:N18) -> 0 | O20: =SUM(O13:O19) -> 30678
C21: POP NOSH | D21: SHAHID | E21: - | F21: 0 | G21: 0 | H21: =F21-G21 -> 0 | I21: =H21-J21 -> 0 | J21: 0 | K21: 0 | L21: 0 | M21: ='03-03-2026'!J66 -> 51257 | N21: 0 | O21: 0
F22: =SUM(F21) -> 0 | G22: =SUM(G21) -> 0 | H22: =SUM(H21) -> 0 | I22: =SUM(I21) -> 0 | J22: =SUM(J21) -> 0 | K22: =SUM(K21) -> 0 | L22: =SUM(L21) -> 0 | M22: =SUM(M21) -> 51257 | ... O22: =SUM(O21) -> 0
C23: Imported Items | D23: SHAHZAD AHMAD | E23: - | F23: 0 | G23: 0 | H23: =F23-G23 -> 0 | I23: =H23-J23 -> 0 | J23: 0 | K23: 0 | L23: 0 | M23: ='03-03-2026'!J77 -> 33969 | N23: 0 | O23: 0
C24: Imported Items | D24: SHAHID | E24: - | F24: 0 | G24: 0 | H24: =F24-G24 -> 0 | I24: =H24-J24 -> 0 | J24: 0 | K24: 0 | L24: 0 | M24: ='03-03-2026'!J78 -> 160846 | N24: 0 | O24: 0
C25: Total | F25: =SUM(F23:F24) -> 0 | G25: =SUM(G23:G24) -> 0 | H25: =SUM(H23:H24) -> 0 | I25: =SUM(I23:I24) -> 0 | J25: =SUM(J23:J24) -> 0 | K25: =SUM(K23:K24) -> 0 | L25: =SUM(L23:L24) -> 0 | M25: =SUM(M23:M24) -> 194815 | ... O25: =SUM(O23:O24) -> 0
C26: TAHORA | D26: SHAHZAD AHMAD | E26: - | F26: 0 | G26: 0 | H26: =F26-G26 -> 0 | I26: =H26-J26 -> 0 | J26: 0 | K26: 0 | L26: 0 | M26: ='03-03-2026'!J81 -> 89658 | N26: 0 | O26: 0
C27: TAHORA | D27: MURTAZA | E27: - | F27: 0 | G27: 0 | H27: =F27-G27 -> 0 | I27: =H27-J27 -> 0 | J27: 0 | K27: 0 | L27: 0 | M27: ='03-03-2026'!J82 -> 42000 | N27: 0 | O27: 0
C28: Total | F28: =SUM(F26:F27) -> 0 | G28: =SUM(G26:G27) -> 0 | H28: =SUM(H26:H27) -> 0 | I28: =SUM(I26:I27) -> 0 | J28: =SUM(J26:J27) -> 0 | K28: =SUM(K26:K27) -> 0 | L28: =SUM(L26:L27) -> 0 | M28: =SUM(M26:M27) -> 131658 | ... O28: =SUM(O26:O27) -> 0
C29: SHAN | D29: KHAWAR | E29: Counter Sale | F29: 21438 | G29: 0 | H29: =F29-G29 -> 21438 | I29: =H29-J29 -> 21438 | J29: 0 | K29: 0 | L29: 0 | M29: ='03-03-2026'!J69 -> 1479248 | N29: 0 | O29: 34576
C30: SHAN | D30: MURTAZA | E30: - | F30: 0 | G30: 0 | H30: =F30-G30 -> 0 | I30: =H30-J30 -> 0 | J30: 0 | K30: 0 | L30: 0 | M30: ='03-03-2026'!J70 -> 174473 | N30: 0 | O30: 0
C31: SHAN | D31: DANISH | E31: - | F31: 0 | G31: 0 | H31: =F31-G31 -> 0 | I31: =H31-J31 -> 0 | J31: 0 | K31: 0 | L31: 0 | M31: ='03-03-2026'!J71 -> 35126 | N31: 0 | O31: 0
C32: SHAN | D32: ASHRAF | E32: Sami | F32: 54300 | G32: 0 | H32: =F32-G32 -> 54300 | I32: =H32-J32 -> 50934 | J32: 3366 | K32: 0 | L32: 0 | M32: ='03-03-2026'!J72 -> 1370709 | N32: 0 | O32: 35646
C33: Total | F33: =SUM(F29:F32) -> 75738 | G33: =SUM(G29:G32) -> 0 | H33: =SUM(H29:H32) -> 75738 | I33: =SUM(I29:I32) -> 72372 | J33: =SUM(J29:J32) -> 3366 | K33: =SUM(K29:K32) -> 0 | L33: =SUM(L29:L32) -> 0 | M33: =SUM(M29:M32) -> 3059556 | ... O33: =SUM(O29:O32) -> 70222
C34: NET TOTAL | F34: =F33+F28+F25+F22+F20+F12 -> 1412063 | G34: =G33+G28+G25+G22+G20+G12 -> 1504 | H34: =H33+H28+H25+H22+H20+H12 -> 1410559 | I34: =I33+I28+I25+I22+I20+I12 -> 1267646 | J34: =J33+J28+J25+J22+J20+J12 -> 142913 | K34: =K33+K28+K25+K22+K20+K12 -> 0 | L34: =L33+L28+L25+L22+L20+L12 -> 3797 | M34: =M33+M28+M25+M22+M20+M12 -> 12692175 | ... O34: =O33+O28+O25+O22+O20+O12 -> 270181
F35: CBL Cash | G35: =O12+L12+J12-K12 -> 244835
F36: CDM Cash | G36: =O20+L20+J20-K20+O22+L22+J22-K22 -> 98468 | I36: Amount | J36: MCB Onlines | K36: Value | M36: Detail
C37: Onlines | F37: Imported Item Cash | G37: =O25+L25+J25-K25 -> 0
F38: TAHORA | G38: =O28+L28+J28-K28 -> 0
F39: Shan Food's Cash | G39: =O33+L33+J33-K33 -> 73588
F40: Total Cash | G40: =SUM(G35:G39) -> 416891
H50: Today Credit Closed
...

Sheet 05-03-2026
C2: 46086
C3: Daily Cash Flow Statement
C4: Companies | D4: Order Bookers | E4: Suppliers | F4: Today Supply | G4: Return Stock | H4: Posting | I4: Credit Posted | J4: Summary Cash | K4: Claim Cleard By Suppliers | L4: Sabqa Payment By Suppliers | M4: Recovery List | N4: Return Stock/Claim Clear By OB | O4: Total Recovery
C5: CBL | D5: Danish | E5: Ayoub | F5: 17850 | G5: 0 | H5: =F5-G5 -> 17850 | I5: =H5-J5 -> 17850 | J5: 0 | K5: 0 | L5: 0 | M5: ='04-03-2026'!J52 -> 347450 | N5: 0 | O5: 43102
C6: CBL | D6: Danish ws | E6: Ayoub | F6: 0 | G6: 0 | H6: =F6-G6 -> 0 | I6: =H6-J6 -> 0 | J6: 0 | K6: 0 | L6: 0 | M6: ='04-03-2026'!J53 -> 3561859 | N6: 0 | O6: 181758
C7: CBL | D7: Murtaza | E7: Ayoub | F7: 104887 | G7: 0 | H7: =F7-G7 -> 104887 | I7: =H7-J7 -> 98743 | J7: 6144 | K7: 0 | L7: 0 | M7: ='04-03-2026'!J54 -> 1158223 | N7: 0 | O7: 30060
C8: CBL | D8: Ali | E8: Awais | F8: 96421 | G8: 715 | H8: =F8-G8 -> 95706 | I8: =H8-J8 -> 85686 | J8: 10020 | K8: 0 | L8: 0 | M8: ='04-03-2026'!J55 -> 846993 | N8: 0 | O8: 58113
C9: CBL | D9: Kashif | E9: Aqib | F9: 90165 | G9: 0 | H9: =F9-G9 -> 90165 | I9: =H9-J9 -> 74458 | J9: 15707 | K9: 0 | L9: 0 | M9: ='04-03-2026'!J56 -> 1242441 | N9: 0 | O9: 10625
C10: CBL | D10: Anas | E10: Awais | F10: 52820 | G10: 504 | H10: =F10-G10 -> 52316 | I10: =H10-J10 -> 42589 | J10: 9727 | K10: 0 | L10: 0 | M10: ='04-03-2026'!J57 -> 455090 | N10: 0 | O10: 47952
C11: Total | F11: =SUM(F5:F10) -> 362143 | G11: =SUM(G5:G10) -> 1219 | H11: =SUM(H5:H10) -> 360924 | I11: =SUM(I5:I10) -> 319326 | J11: =SUM(J5:J10) -> 41598 | K11: =SUM(K5:K10) -> 0 | L11: =SUM(L5:L10) -> 0 | M11: =SUM(M5:M10) -> 7612056 | ... O11: =SUM(O5:O10) -> 371610
C12: CDM/TANG | D12: QADEER | E12: Ikram | F12: 55862 | G12: 5371 | H12: =F12-G12 -> 50491 | I12: =H12-J12 -> 21454 | J12: 29037 | K12: 0 | L12: 0 | M12: ='04-03-2026'!J61 -> 477196 | N12: 0 | O12: 12500
C13: CDM/TANG | D13: SHAHID | E13: Ikram | F13: 112027 | G13: 7335 | H13: =F13-G13 -> 104692 | I13: =H13-J13 -> 80386 | J13: 24306 | K13: 0 | L13: 0 | M13: ='04-03-2026'!J62 -> 1539466 | N13: 0 | O13: =68480+25000 -> 93480
C14: CDM/TANG | D14: SHAHID | E14: Ikram | F14: 60376 | G14: 0 | H14: =F14-G14 -> 60376 | I14: =H14-J14 -> 60376 | J14: 0
C15: CDM/TANG | D15: DANISH | E15: Sami | F15: 0 | G15: 0 | H15: =F15-G15 -> 0 | I15: =H15-J15 -> 0 | J15: 0 | K15: 0 | L15: 0 | M15: ='04-03-2026'!J63 -> 617689 | N15: 0 | O15: 102077
C16: CDM/TANG | D16: Kashif | E16: Awais | F16: 0 | G16: 0 | H16: =F16-G16 -> 0 | I16: =H16-J16 -> 0 | J16: 0 | K16: 0 | L16: 0 | M16: 0 | N16: 0 | O16: 0
C17: CDM/TANG | D17: Murtaza | E17: Aqib/Faiz | F17: 0 | G17: 0 | H17: =F17-G17 -> 0 | I17: =H17-J17 -> 0 | J17: 0 | K17: 0 | L17: 0 | M17: 0 | N17: 0 | O17: 0
C18: CDM/TANG | F18: =SUM(F12:F17) -> 228265 | G18: =SUM(G12:G17) -> 12706 | H18: =SUM(H12:H16) -> 215559 | I18: =SUM(I12:I16) -> 162216 | J18: =SUM(J12:J17) -> 53343 | K18: =SUM(K12:K16) -> 0 | L18: =SUM(L12:L16) -> 0 | M18: =SUM(M12:M17) -> 2634351 | N18: =SUM(N12:N16) -> 0 | O18: =SUM(O12:O17) -> 208057
C19: POP NOSH | D19: SHAHID | E19: - | F19: 0 | G19: 0 | H19: =F19-G19 -> 0 | I19: =H19-J19 -> 0 | J19: 0 | K19: 0 | L19: 0 | M19: ='04-03-2026'!J65 -> 51257 | N19: 0 | O19: 0
F20: =SUM(F19) -> 0 | G20: =SUM(G19) -> 0 | H20: =SUM(H19) -> 0 | I20: =SUM(I19) -> 0 | J20: =SUM(J19) -> 0 | K20: =SUM(K19) -> 0 | L20: =SUM(L19) -> 0 | M20: =SUM(M19) -> 51257 | ... O20: =SUM(O19) -> 0
C21: Imported Items | D21: SHAHZAD AHMAD | E21: - | F21: 0 | G21: 0 | H21: =F21-G21 -> 0 | I21: =H21-J21 -> 0 | J21: 0 | K21: 0 | L21: 0 | M21: ='04-03-2026'!J76 -> 33969 | N21: 0 | O21: 0
C22: Imported Items | D22: SHAHID | E22: - | F22: 0 | G22: 0 | H22: =F22-G22 -> 0 | I22: =H22-J22 -> 0 | J22: 0 | K22: 0 | L22: 0 | M22: =SUM(M21) -> 33969 | N22: 0 | O22: 15000
C23: Total | F23: =SUM(F21:F22) -> 0 | G23: =SUM(G21:G22) -> 0 | H23: =SUM(H21:H22) -> 0 | I23: =SUM(I21:I22) -> 0 | J23: =SUM(J21:J22) -> 0 | K23: =SUM(K21:K22) -> 0 | L23: =SUM(L21:L22) -> 0 | M23: =SUM(M21:M22) -> 67938 | ... O23: =SUM(O21:O22) -> 15000
C24: TAHORA | D24: SHAHZAD AHMAD | E24: - | F24: 0 | G24: 0 | H24: =F24-G24 -> 0 | I24: =H24-J24 -> 0 | J24: 0 | K24: 0 | L24: 0 | M24: ='04-03-2026'!J80 -> 89658 | N24: 0 | O24: 0
C25: TAHORA | D25: MURTAZA | E25: - | F25: 0 | G25: 0 | H25: =F25-G25 -> 0 | I25: =H25-J25 -> 0 | J25: 0 | K25: 0 | L25: 0 | M25: ='04-03-2026'!J81 -> 42000 | N25: 0 | O25: 25000
C26: Total | F26: =SUM(F24:F25) -> 0 | G26: =SUM(G24:G25) -> 0 | H26: =SUM(H24:H25) -> 0 | I26: =SUM(I24:I25) -> 0 | J26: =SUM(J24:J25) -> 0 | K26: =SUM(K24:K25) -> 0 | L26: =SUM(L24:L25) -> 0 | M26: =SUM(M24:M25) -> 131658 | ... O26: =SUM(O24:O25) -> 25000
C27: SHAN | D27: KHAWAR | E27: Aqib | F27: 24297 | G27: 0 | H27: =F27-G27 -> 24297 | I27: =H27-J27 -> 24297 | J27: 0 | K27: 0 | L27: 0 | M27: ='04-03-2026'!J68 -> 1466110 | N27: 0 | O27: 39872
C28: SHAN | D28: MURTAZA | E28: - | F28: 0 | G28: 0 | H28: =F28-G28 -> 0 | I28: =H28-J28 -> 0 | J28: 0 | K28: 0 | L28: 0 | M28: ='04-03-2026'!J69 -> 174473 | N28: 0 | O28: 0
C29: SHAN | D29: DANISH | E29: - | F29: 0 | G29: 0 | H29: =F29-G29 -> 0 | I29: =H29-J29 -> 0 | J29: 0 | K29: 0 | L29: 0 | M29: ='04-03-2026'!J70 -> 35126 | N29: 0 | O29: 0
C30: SHAN | D30: ASHRAF | E30: Ayoub | F30: 32354 | G30: 0 | H30: =F30-G30 -> 32354 | I30: =H30-J30 -> 31931 | J30: 423 | K30: 0 | L30: 500 | M30: ='04-03-2026'!J71 -> 1385997 | N30: 0 | O30: 71326
C31: Total | F31: =SUM(F27:F30) -> 56651 | G31: =SUM(G27:G30) -> 0 | H31: =SUM(H27:H30) -> 56651 | I31: =SUM(I27:I30) -> 56228 | J31: =SUM(J27:J30) -> 423 | K31: =SUM(K27:K30) -> 0 | L31: =SUM(L27:L30) -> 500 | M31: =SUM(M27:M30) -> 3061706 | ... O31: =SUM(O27:O30) -> 111198
C32: NET TOTAL | F32: =F31+F26+F23+F20+F18+F11 -> 647059 | G32: =G31+G26+G23+G20+G18+G11 -> 13925 | H32: =H31+H26+H23+H20+H18+H11 -> 633134 | I32: =I31+I26+I23+I20+I18+I11 -> 537770 | J32: =J31+J26+J23+J20+J18+J11 -> 95364 | K32: =K31+K26+K23+K20+K18+K11 -> 0 | L32: =L31+L26+L23+L20+L18+L11 -> 500 | M32: =M31+M26+M23+M20+M18+M11 -> 13558966 | ... O32: =O31+O26+O23+O20+O18+O11 -> 730865
F33: CBL Cash | G33: =O11+L11+J11-K11 -> 413208
F34: CDM Cash | G34: =O18+L18+J18-K18+O20+L20+J20-K20 -> 261400 | I34: Amount | J34: MCB Onlines | K34: Value | M34: Detail
C35: Onlines | F35: Imported Item Cash | G35: =O23+L23+J23-K23 -> 15000
F36: TAHORA | G36: =O26+L26+J26-K26 -> 25000
F37: Shan Food's Cash | G37: =O31+L31+J31-K31 -> 112121
F38: Total Cash | G38: =SUM(G33:G37) -> 826729
H48: Today Credit Closed
H49: COMPANY | I49: ODERBOOKERS | J49: CREDIT AMOUNT
H50: CBL | I50: Danish | J50: =M5-O5-N5-L5+I5 -> 322198 | K50: 359515 | L50: =J50-K50 -> -37317
...

Sheet 07-03-2026
C2: 46088
C3: Daily Cash Flow Statement
C4: Companies | D4: Order Bookers | E4: Suppliers | F4: Today Supply | G4: Return Stock | H4: Posting | I4: Credit Posted | J4: Summary Cash | K4: Claim Cleard By Suppliers | L4: Sabqa Payment By Suppliers | M4: Recovery List | N4: Return Stock/Claim Clear By OB | O4: Total Recovery
C5: CBL | D5: Danish | E5: Ayoub | F5: 0 | G5: 0 | H5: =F5-G5 -> 0 | I5: =H5-J5 -> 0 | J5: 0 | K5: 0 | L5: 0 | M5: ='05-03-2026'!J50 -> 322198 | N5: 0 | O5: 0
C6: CBL | D6: Danish ws | E6: Ayoub | F6: 269459 | G6: 0 | H6: =F6-G6 -> 269459 | I6: =H6-J6 -> 262977 | J6: 6482 | K6: 0 | L6: 0 | M6: ='05-03-2026'!J51 -> 3380101 | N6: 0 | O6: 0
C7: CBL | D7: Murtaza | E7: Aqib | F7: 86320 | G7: 0 | H7: =F7-G7 -> 86320 | I7: =H7-J7 -> 63511 | J7: 22809 | K7: 0 | L7: 0 | M7: ='05-03-2026'!J52 -> 1226906 | N7: 0 | O7: 50318
C8: CBL | D8: Ali | E8: Awais | F8: 100043 | G8: 0 | H8: =F8-G8 -> 100043 | I8: =H8-J8 -> 85722 | J8: 14321 | K8: 0 | L8: 0 | M8: ='05-03-2026'!J53 -> 874566 | N8: 0 | O8: 57269
C9: CBL | D9: Kashif | E9: Aqib | F9: 110270 | G9: 0 | H9: =F9-G9 -> 110270 | I9: =H9-J9 -> 45284 | J9: 64986 | K9: 0 | L9: 0 | M9: ='05-03-2026'!J54 -> 1306274 | N9: 0 | O9: 44116
C10: CBL | D10: Anas | E10: Saad | F10: 85340 | G10: 0 | H10: =F10-G10 -> 85340 | I10: =H10-J10 -> 66589 | J10: 18751 | K10: 0 | L10: 0 | M10: ='05-03-2026'!J55 -> 449727 | N10: 0 | O10: 0
C11: Total | F11: =SUM(F5:F10) -> 651432 | G11: =SUM(G5:G10) -> 0 | H11: =SUM(H5:H10) -> 651432 | I11: =SUM(I5:I10) -> 524083 | J11: =SUM(J5:J10) -> 127349 | K11: =SUM(K5:K10) -> 0 | L11: =SUM(L5:L10) -> 0 | M11: =SUM(M5:M10) -> 7559772 | ... O11: =SUM(O5:O10) -> 151703
C12: CDM/TANG | D12: QADEER | E12: Ikram | F12: 128199 | G12: 3614 | H12: =F12-G12 -> 124585 | I12: =H12-J12 -> 34681 | J12: 89904 | K12: 0 | L12: 0 | M12: ='05-03-2026'!J59 -> 486150 | N12: 0 | O12: 61657
C13: CDM/TANG | D13: SHAHID | E13: Ikram | F13: 189463 | G13: 11221 | H13: =F13-G13 -> 178242 | I13: =H13-J13 -> 108290 | J13: 69952 | K13: 0 | L13: 0 | M13: ='05-03-2026'!J60 -> 1586748 | N13: 0 | O13: 149436
C14: CDM/TANG | D14: SHAHID | E14: Counter Sale | F14: 10095 | G14: 0 | H14: =F14-G14 -> 10095 | I14: =H14-J14 -> 0 | J14: 10095 | K14: 0 | L14: 0 | M14: 0 | N14: 0 | O14: 0
C15: CDM/TANG | D15: DANISH | E15: Sami | F15: 0 | G15: 0 | H15: =F15-G15 -> 0 | I15: =H15-J15 -> 0 | J15: 0 | K15: 0 | L15: 0 | M15: ='05-03-2026'!J61 -> 515612 | N15: 0 | O15: 0
C16: CDM/TANG | D16: Kashif | E16: Aqib | F16: 20209 | G16: 0 | H16: =F16-G16 -> 20209 | I16: =H16-J16 -> 0 | J16: 20209 | K16: 0 | L16: 0 | M16: 0 | N16: 0 | O16: 0
C17: CDM/TANG | D17: Murtaza | E17: Aqib/Faiz | F17: 12970 | G17: 0 | H17: =F17-G17 -> 12970 | I17: =H17-J17 -> 0 | J17: 12970 | K17: 0 | L17: 0 | M17: 0 | N17: 0 | O17: 0
C18: CDM/TANG | F18: =SUM(F12:F17) -> 360936 | G18: =SUM(G12:G17) -> 14835 | H18: =SUM(H12:H16) -> 333131 | I18: =SUM(I12:I16) -> 142971 | J18: =SUM(J12:J17) -> 203130 | K18: =SUM(K12:K16) -> 0 | L18: =SUM(L12:L16) -> 0 | M18: =SUM(M12:M17) -> 2588510 | N18: =SUM(N12:N16) -> 0 | O18: =SUM(O12:O17) -> 211093
C19: POP NOSH | D19: SHAHID | E19: - | F19: 0 | G19: 0 | H19: =F19-G19 -> 0 | I19: =H19-J19 -> 0 | J19: 0 | K19: 0 | L19: 0 | M19: ='05-03-2026'!J63 -> 51257 | N19: 0 | O19: 0
F20: =SUM(F19) -> 0 | G20: =SUM(G19) -> 0 | H20: =SUM(H19) -> 0 | I20: =SUM(I19) -> 0 | J20: =SUM(J19) -> 0 | K20: =SUM(K19) -> 0 | L20: =SUM(L19) -> 0 | M20: =SUM(M19) -> 51257 | ... O20: =SUM(O19) -> 0
C21: Imported Items | D21: SHAHZAD AHMAD | E21: - | F21: 0 | G21: 0 | H21: =F21-G21 -> 0 | I21: =H21-J21 -> 0 | J21: 0 | K21: 0 | L21: 0 | M21: ='05-03-2026'!J74 -> 33969 | N21: 0 | O21: 0
C22: Imported Items | D22: SHAHID | E22: - | F22: 0 | G22: 0 | H22: =F22-G22 -> 0 | I22: =H22-J22 -> 0 | J22: 0 | K22: 0 | L22: 0 | M22: ='05-03-2026'!J75 -> 18969 | N22: 0 | O22: 0
C23: Total | F23: =SUM(F21:F22) -> 0 | G23: =SUM(G21:G22) -> 0 | H23: =SUM(H21:H22) -> 0 | I23: =SUM(I21:I22) -> 0 | J23: =SUM(J21:J22) -> 0 | K23: =SUM(K21:K22) -> 0 | L23: =SUM(L21:L22) -> 0 | M23: =SUM(F23:L23) -> 0 | N23: =SUM(N21:N22) -> 0 | O23: =SUM(O21:O22) -> 0
C24: TAHORA | D24: SHAHZAD AHMAD | E24: - | F24: 0 | G24: 0 | H24: =F24-G24 -> 0 | I24: =H24-J24 -> 0 | J24: 0 | K24: 0 | L24: 0 | M24: ='05-03-2026'!J78 -> 89658 | N24: 0 | O24: 0
C25: TAHORA | D25: MURTAZA | E25: - | F25: 0 | G25: 0 | H25: =F25-G25 -> 0 | I25: =H25-J25 -> 0 | J25: 0 | K25: 0 | L25: 0 | M25: ='05-03-2026'!J79 -> 17000 | N25: 0 | O25: 0
C26: Total | F26: =SUM(F24:F25) -> 0 | G26: =SUM(G24:G25) -> 0 | H26: =SUM(H24:H25) -> 0 | I26: =SUM(I24:I25) -> 0 | J26: =SUM(J24:J25) -> 0 | K26: =SUM(K24:K25) -> 0 | L26: =SUM(L24:L25) -> 0 | M26: =SUM(M24:M25) -> 106658 | ... O26: =SUM(O24:O25) -> 0
C27: SHAN | D27: KHAWAR | E27: Aqib | F27: 21407 | G27: 0 | H27: =F27-G27 -> 21407 | I27: =H27-J27 -> 18707 | J27: 2700 | K27: 0 | L27: 0 | M27: ='05-03-2026'!J66 -> 1450535 | N27: 0 | O27: 60240
C28: SHAN | D28: MURTAZA | E28: - | F28: 0 | G28: 0 | H28: =F28-G28 -> 0 | I28: =H28-J28 -> 0 | J28: 0 | K28: 0 | L28: 0 | M28: ='05-03-2026'!J67 -> 174473 | N28: 0 | O28: 0
C29: SHAN | D29: DANISH | E29: - | F29: 0 | G29: 0 | H29: =F29-G29 -> 0 | I29: =H29-J29 -> 0 | J29: 0 | K29: 0 | L29: 0 | M29: ='05-03-2026'!J68 -> 35126 | N29: 0 | O29: 0
C30: SHAN | D30: ASHRAF | E30: Ayoub | F30: 0 | G30: 0 | H30: =F30-G30 -> 0 | I30: =H30-J30 -> 0 | J30: 0 | K30: 0 | L30: 0 | M30: ='05-03-2026'!J69 -> 1346102 | N30: 0 | O30: 52535
C31: Total | F31: =SUM(F27:F30) -> 21407 | G31: =SUM(G27:G30) -> 0 | H31: =SUM(H27:H30) -> 21407 | I31: =SUM(I27:I30) -> 18707 | J31: =SUM(J27:J30) -> 2700 | K31: =SUM(K27:K30) -> 0 | L31: =SUM(L27:L30) -> 0 | M31: =SUM(M27:M30) -> 3006236 | ... O31: =SUM(O27:O30) -> 112775
C32: NET TOTAL | F32: =F31+F26+F23+F20+F18+F11 -> 1033775 | G32: =G31+G26+G23+G20+G18+G11 -> 14835 | H32: =H31+H26+H23+H20+H18+H11 -> 1005970 | I32: =I31+I26+I23+I20+I18+I11 -> 685761 | J32: =J31+J26+J23+J20+J18+J11 -> 333179 | K32: =K31+K26+K23+K20+K18+K11 -> 0 | L32: =L31+L26+L23+L20+L18+L11 -> 0 | M32: =M31+M26+M23+M20+M18+M11 -> 13312433 | ... O32: =O31+O26+O23+O20+O18+O11 -> 475571
F33: CBL Cash | G33: =O11+L11+J11-K11 -> 279052
F34: CDM Cash | G34: =O18+L18+J18-K18+O20+L20+J20-K20 -> 414223 | I34: Amount | J34: MCB Onlines | K34: Value | M34: Detail
C35: Onlines | F35: Imported Item Cash | G35: =O23+L23+J23-K23 -> 0
F36: TAHORA | G36: =O26+L26+J26-K26 -> 0
F37: Shan Food's Cash | G37: =O31+L31+J31-K31 -> 115475
F38: Total Cash | G38: =SUM(G33:G37) -> 808750
H48: Today Credit Closed
H49: COMPANY | I49: ODERBOOKERS | J49: CREDIT AMOUNT
H50: CBL | I50: Danish | J50: =M5-O5-N5-L5+I5 -> 322198 | K50: 359515 | L50: =J50-K50 -> -37317
...

Sheet 08-03-2026
C2: 46089
C3: Daily Cash Flow Statement
C4: Companies | D4: Order Bookers | E4: Suppliers | F4: Today Supply | G4: Return Stock | H4: Posting | I4: Credit Posted | J4: Summary Cash | K4: Claim Cleard By Suppliers | L4: Sabqa Payment By Suppliers | M4: Recovery List | N4: Return Stock/Claim Clear By OB | O4: Total Recovery
C5: CBL | D5: Danish | F5: 0 | G5: 0 | H5: =F5-G5 -> 0 | I5: =H5-J5 -> 0 | J5: 0 | K5: 0 | L5: 0 | M5: ='07-03-2026'!J50 -> 322198 | N5: 0 | O5: 31765
C6: CBL | D6: Danish ws | E6: Ayoub | F6: 615746 | G6: 0 | H6: =F6-G6 -> 615746 | I6: =H6-J6 -> 615746 | J6: 0 | K6: 0 | L6: 0 | M6: ='07-03-2026'!J51 -> 3643078 | N6: 0 | O6: 618534
C7: CBL | D7: Murtaza | E7: Saad | F7: 91897 | G7: 0 | H7: =F7-G7 -> 91897 | I7: =H7-J7 -> 72571 | J7: 19326 | K7: 0 | L7: 0 | M7: ='07-03-2026'!J52 -> 1240099 | N7: 0 | O7: 80456
C8: CBL | D8: Ali | E8: Awais | F8: 165963 | G8: 0 | H8: =F8-G8 -> 165963 | I8: =H8-J8 -> 153668 | J8: 12295 | K8: 0 | L8: 0 | M8: ='07-03-2026'!J53 -> 903019 | N8: 0 | O8: 58892
C9: CBL | D9: Kashif | E9: Aqib | F9: 74957 | G9: 0 | H9: =F9-G9 -> 74957 | I9: =H9-J9 -> 66644 | J9: 8313 | K9: 0 | L9: 2000 | M9: ='07-03-2026'!J54 -> 1307442 | N9: 0 | O9: 25701
C10: CBL | D10: Anas | E10: Aqib | F10: 69330 | G10: 2662 | H10: =F10-G10 -> 66668 | I10: =H10-J10 -> 42848 | J10: 23820 | K10: 0 | L10: 0 | M10: ='07-03-2026'!J55 -> 516316 | N10: 0 | O10: 49504
C11: Total | F11: =SUM(F5:F10) -> 1017893 | G11: =SUM(G5:G10) -> 2662 | H11: =SUM(H5:H10) -> 1015231 | I11: =SUM(I5:I10) -> 951477 | J11: =SUM(J5:J10) -> 63754 | K11: =SUM(K5:K10) -> 0 | L11: =SUM(L5:L10) -> 2000 | M11: =SUM(M5:M10) -> 7932152 | ... O11: =SUM(O5:O10) -> 864852
C12: CDM/TANG | D12: QADEER | E12: Ikram | F12: 91895 | G12: 1056 | H12: =F12-G12 -> 90839 | I12: =H12-J12 -> 69709 | J12: 21130 | K12: 0 | L12: 0 | M12: ='07-03-2026'!J59 -> 459174 | N12: 0 | O12: 59834
C13: CDM/TANG | D13: QADEER | E13: Counter Sale | F13: 844 | G13: 0 | H13: =F13-G13 -> 844 | I13: =H13-J13 -> 0 | J13: 844
C14: CDM/TANG | D14: SHAHID | E14: Ikram | F14: 183851 | G14: 1842 | H14: =F14-G14 -> 182009 | I14: =H14-J14 -> 122440 | J14: 59569 | K14: 0 | L14: 10394 | M14: ='07-03-2026'!J60 -> 1545602 | N14: 0 | O14: 0
C15: CDM/TANG | D15: SHAHID | E15: Counter Sale | F15: 3207 | G15: 0 | H15: =F15-G15 -> 3207 | I15: =H15-J15 -> 0 | J15: 3207
C16: CDM/TANG | D16: DANISH | F16: 0 | G16: 0 | H16: =F16-G16 -> 0 | I16: =H16-J16 -> 0 | J16: 0 | K16: 0 | L16: 0 | M16: ='07-03-2026'!J61 -> 515612 | N16: 0 | O16: 90000
C17: CDM/TANG | D17: Kashif | E17: Aqib | F17: 36281 | G17: 0 | H17: =F17-G17 -> 36281 | I17: =H17-J17 -> 0 | J17: 36281 | K17: 0 | L17: 0 | M17: 0 | N17: 0 | O17: 0
C18: CDM/TANG | D18: Murtaza | F18: 0 | G18: 0 | H18: =F18-G18 -> 0 | I18: =H18-J18 -> 0 | J18: 0 | K18: 0 | L18: 0 | M18: 0 | N18: 0 | O18: 0
C19: CDM/TANG | F19: =SUM(F12:F18) -> 316078 | G19: =SUM(G12:G18) -> 2898 | H19: =SUM(H12:H17) -> 313180 | I19: =SUM(I12:I17) -> 192149 | J19: =SUM(J12:J18) -> 121031 | K19: =SUM(K12:K17) -> 0 | L19: =SUM(L12:L17) -> 10394 | M19: =SUM(M12:M18) -> 2520388 | N19: =SUM(N12:N17) -> 0 | O19: =SUM(O12:O18) -> 149834
C20: POP NOSH | D20: SHAHID | E20: - | F20: 0 | G20: 0 | H20: =F20-G20 -> 0 | I20: =H20-J20 -> 0 | J20: 0 | K20: 0 | L20: 0 | M20: ='07-03-2026'!J63 -> 51257 | N20: 0 | O20: 0
F21: =SUM(F20) -> 0 | G21: =SUM(G20) -> 0 | H21: =SUM(H20) -> 0 | I21: =SUM(I20) -> 0 | J21: =SUM(J20) -> 0 | K21: =SUM(K20) -> 0 | L21: =SUM(L20) -> 0 | M21: =SUM(M20) -> 51257 | ... O21: =SUM(O20) -> 0
C22: Imported Items | D22: SHAHZAD AHMAD | E22: - | F22: 0 | G22: 0 | H22: =F22-G22 -> 0 | I22: =H22-J22 -> 0 | J22: 0 | K22: 0 | L22: 0 | M22: ='07-03-2026'!J74 -> 33969 | N22: 0 | O22: 0
C23: Imported Items | D23: SHAHID | E23: - | F23: 0 | G23: 0 | H23: =F23-G23 -> 0 | I23: =H23-J23 -> 0 | J23: 0 | K23: 0 | L23: 0 | M23: ='07-03-2026'!J75 -> 18969 | N23: 0 | O23: 0
C24: Total | F24: =SUM(F22:F23) -> 0 | G24: =SUM(G22:G23) -> 0 | H24: =SUM(H22:H23) -> 0 | I24: =SUM(I22:I23) -> 0 | J24: =SUM(J22:J23) -> 0 | K24: =SUM(K22:K23) -> 0 | L24: =SUM(L22:L23) -> 0 | M24: =SUM(F24:L24) -> 0 | N24: =SUM(N22:N23) -> 0 | O24: =SUM(O22:O23) -> 0
C25: TAHORA | D25: SHAHZAD AHMAD | E25: - | F25: 0 | G25: 0 | H25: =F25-G25 -> 0 | I25: =H25-J25 -> 0 | J25: 0 | K25: 0 | L25: 0 | M25: ='07-03-2026'!J78 -> 89658 | N25: 0 | O25: 0
C26: TAHORA | D26: MURTAZA | E26: - | F26: 0 | G26: 0 | H26: =F26-G26 -> 0 | I26: =H26-J26 -> 0 | J26: 0 | K26: 0 | L26: 0 | M26: ='07-03-2026'!J79 -> 17000 | N26: 0 | O26: 0
C27: Total | F27: =SUM(F25:F26) -> 0 | G27: =SUM(G25:G26) -> 0 | H27: =SUM(H25:H26) -> 0 | I27: =SUM(I25:I26) -> 0 | J27: =SUM(J25:J26) -> 0 | K27: =SUM(K25:K26) -> 0 | L27: =SUM(L25:L26) -> 0 | M27: =SUM(M25:M26) -> 106658 | ... O27: =SUM(O25:O26) -> 0
C28: SHAN | D28: KHAWAR | E28: Awais | F28: 54615 | G28: 0 | H28: =F28-G28 -> 54615 | I28: =H28-J28 -> 54615 | J28: 0 | K28: 0 | L28: 0 | M28: ='07-03-2026'!J66 -> 1409002 | N28: 0 | O28: 31589
C29: SHAN | D29: MURTAZA | E29: - | F29: 0 | G29: 0 | H29: =F29-G29 -> 0 | I29: =H29-J29 -> 0 | J29: 0 | K29: 0 | L29: 0 | M29: ='07-03-2026'!J67 -> 174473 | N29: 0 | O29: 0
C30: SHAN | D30: DANISH | E30: - | F30: 0 | G30: 0 | H30: =F30-G30 -> 0 | I30: =H30-J30 -> 0 | J30: 0 | K30: 0 | L30: 0 | M30: ='07-03-2026'!J68 -> 35126 | N30: 0 | O30: 0
C31: SHAN | D31: ASHRAF | E31: Sami | F31: 183767 | G31: 20640 | H31: =F31-G31 -> 163127 | I31: =H31-J31 -> 160131 | J31: 2996 | K31: 0 | L31: 0 | M31: ='07-03-2026'!J69 -> 1293567 | N31: 0 | O31: 34385
C32: Total | F32: =SUM(F28:F31) -> 238382 | G32: =SUM(G28:G31) -> 20640 | H32: =SUM(H28:H31) -> 217742 | I32: =SUM(I28:I31) -> 214746 | J32: =SUM(J28:J31) -> 2996 | K32: =SUM(K28:K31) -> 0 | L32: =SUM(L28:L31) -> 0 | M32: =SUM(M28:M31) -> 2912168 | ... O32: =SUM(O28:O31) -> 65974
C33: NET TOTAL | F33: =F32+F27+F24+F21+F19+F11 -> 1572353 | G33: =G32+G27+G24+G21+G19+G11 -> 26200 | H33: =H32+H27+H24+H21+H19+H11 -> 1546153 | I33: =I32+I27+I24+I21+I19+I11 -> 1358372 | J33: =J32+J27+J24+J21+J19+J11 -> 187781 | K33: =K32+K27+K24+K21+K19+K11 -> 0 | L33: =L32+L27+L24+L21+L19+L11 -> 12394 | M33: =M32+M27+M24+M21+M19+M11 -> 13522623 | ... O33: =O32+O27+O24+O21+O19+O11 -> 1080660
F34: CBL Cash | G34: =O11+L11+J11-K11 -> 930606
F35: CDM Cash | G35: =O19+L19+J19-K19+O21+L21+J21-K21 -> 281259 | I35: Amount | J35: MCB Onlines | K35: Value | M35: Detail
C36: Onlines | F36: Imported Item Cash | G36: =O24+L24+J24-K24 -> 0
F37: TAHORA | G37: =O27+L27+J27-K27 -> 0
F38: Shan Food's Cash | G38: =O32+L32+J32-K32 -> 68970
F39: Total Cash | G39: =SUM(G34:G38) -> 1280835
H49: Today Credit Closed
H50: COMPANY | I50: ODERBOOKERS | J50: CREDIT AMOUNT
...

Sheet 09-03-2026
C2: 46090
C3: Daily Cash Flow Statement
C4: Companies | D4: Order Bookers | E4: Suppliers | F4: Today Supply | G4: Return Stock | H4: Posting | I4: Credit Posted | J4: Summary Cash | K4: Claim Cleard By Suppliers | L4: Sabqa Payment By Suppliers | M4: Recovery List | N4: Return Stock/Claim Clear By OB | O4: Total Recovery
C5: CBL | D5: Danish | E5: Awais | F5: 117124 | G5: 1368 | H5: =F5-G5 -> 115756 | I5: =H5-J5 -> 25478 | J5: 90278 | K5: 0 | L5: 0 | M5: ='08-03-2026'!J51 -> 290433 | N5: 0 | O5: 18226
C6: CBL | D6: Danish ws | E6: Ikram | F6: 0 | G6: 0 | H6: =F6-G6 -> 0 | I6: =H6-J6 -> 0 | J6: 0 | K6: 0 | L6: 0 | M6: ='08-03-2026'!J52 -> 3640290 | N6: 0 | O6: 90000
C7: CBL | D7: Murtaza | E7: Saad | F7: 283633 | G7: 0 | H7: =F7-G7 -> 283633 | I7: =H7-J7 -> 282494 | J7: 1139 | K7: 0 | L7: 0 | M7: ='08-03-2026'!J53 -> 1232214 | N7: 0 | O7: 45927
C8: CBL | D8: Ali | E8: Ikram | F8: 104546 | G8: 0 | H8: =F8-G8 -> 104546 | I8: =H8-J8 -> 94729 | J8: 9817 | K8: 0 | L8: 0 | M8: ='08-03-2026'!J54 -> 997795 | N8: 0 | O8: 59366
C9: CBL | D9: Kashif | E9: Awais | F9: 64344 | G9: 0 | H9: =F9-G9 -> 64344 | I9: =H9-J9 -> 15254 | J9: =50239-1149 -> 49090 | K9: 0 | L9: 0 | M9: ='08-03-2026'!J55 -> 1346385 | N9: 0 | O9: 67006
C10: CBL | D10: Anas | E10: Ayoub | F10: 114949 | G10: 1051 | H10: =F10-G10 -> 113898 | I10: =H10-J10 -> 113898 | J10: 0 | K10: 0 | L10: 0 | M10: ='08-03-2026'!J56 -> 509660 | N10: 0 | O10: 37974
C11: Total | F11: =SUM(F5:F10) -> 684596 | G11: =SUM(G5:G10) -> 2419 | H11: =SUM(H5:H10) -> 682177 | I11: =SUM(I5:I10) -> 531853 | J11: =SUM(J5:J10) -> 150324 | K11: =SUM(K5:K10) -> 0 | L11: =SUM(L5:L10) -> 0 | M11: =SUM(M5:M10) -> 8016777 | ... O11: =SUM(O5:O10) -> 318499
C12: CDM/TANG | D12: QADEER | E12: Sami | F12: 71924 | G12: 668 | H12: =F12-G12 -> 71256 | I12: =H12-J12 -> 43127 | J12: 28129 | K12: 0 | L12: 0 | M12: ='08-03-2026'!J60 -> 469049 | N12: 0 | O12: 66458
C13: CDM/TANG | D13: SHAHID | E13: Awais | F13: 52600 | G13: 446 | H13: =F13-G13 -> 52154 | I13: =H13-J13 -> 7187 | J13: 44967 | K13: 0 | L13: 0 | M13: ='08-03-2026'!J61 -> 1657648 | N13: 0 | O13: 359610
C14: CDM/TANG | D14: SHAHID | E14: Ikram | F14: 59251 | G14: 0 | H14: =F14-G14 -> 59251 | I14: =H14-J14 -> 59251 | J14: 0
C15: CDM/TANG | D15: DANISH | E15: Awais | F15: 70943 | G15: 0 | H15: =F15-G15 -> 70943 | I15: =H15-J15 -> 31565 | J15: 39378 | K15: 0 | L15: 0 | M15: ='08-03-2026'!J62 -> 425612 | N15: 0 | O15: 0
C16: CDM/TANG | D16: Kashif | E16: Awais | F16: 10753 | G16: 0 | H16: =F16-G16 -> 10753 | I16: =H16-J16 -> 0 | J16: 10753 | K16: 0 | L16: 0 | M16: 0 | N16: 0 | O16: 0
C17: CDM/TANG | D17: Murtaza | F17: 0 | G17: 0 | H17: =F17-G17 -> 0 | I17: =H17-J17 -> 0 | J17: 0 | K17: 0 | L17: 0 | M17: 0 | N17: 0 | O17: 0
C18: CDM/TANG | F18: =SUM(F12:F17) -> 265471 | G18: =SUM(G12:G17) -> 1114 | H18: =SUM(H12:H16) -> 264357 | I18: =SUM(I12:I16) -> 141130 | J18: =SUM(J12:J17) -> 123227 | K18: =SUM(K12:K16) -> 0 | L18: =SUM(L12:L16) -> 0 | M18: =SUM(M12:M17) -> 2552309 | N18: =SUM(N12:N16) -> 0 | O18: =SUM(O12:O17) -> 426068
C19: POP NOSH | D19: SHAHID | E19: - | F19: 0 | G19: 0 | H19: =F19-G19 -> 0 | I19: =H19-J19 -> 0 | J19: 0 | K19: 0 | L19: 0 | M19: ='08-03-2026'!J64 -> 51257 | N19: 0 | O19: 0
F20: =SUM(F19) -> 0 | G20: =SUM(G19) -> 0 | H20: =SUM(H19) -> 0 | I20: =SUM(I19) -> 0 | J20: =SUM(J19) -> 0 | K20: =SUM(K19) -> 0 | L20: =SUM(L19) -> 0 | M20: =SUM(M19) -> 51257 | ... O20: =SUM(O19) -> 0
C21: Imported Items | D21: SHAHZAD AHMAD | E21: - | F21: 0 | G21: 0 | H21: =F21-G21 -> 0 | I21: =H21-J21 -> 0 | J21: 0 | K21: 0 | L21: 0 | M21: ='08-03-2026'!J75 -> 33969 | N21: 0 | O21: 0
C22: Imported Items | D22: SHAHID | E22: - | F22: 0 | G22: 0 | H22: =F22-G22 -> 0 | I22: =H22-J22 -> 0 | J22: 0 | K22: 0 | L22: 0 | M22: ='08-03-2026'!J76 -> 18969 | N22: 0 | O22: 0
C23: Total | F23: =SUM(F21:F22) -> 0 | G23: =SUM(G21:G22) -> 0 | H23: =SUM(H21:H22) -> 0 | I23: =SUM(I21:I22) -> 0 | J23: =SUM(J21:J22) -> 0 | K23: =SUM(K21:K22) -> 0 | L23: =SUM(L21:L22) -> 0 | M23: =SUM(F23:L23) -> 0 | N23: =SUM(N21:N22) -> 0 | O23: =SUM(O21:O22) -> 0
C24: TAHORA | D24: SHAHZAD AHMAD | E24: - | F24: 0 | G24: 0 | H24: =F24-G24 -> 0 | I24: =H24-J24 -> 0 | J24: 0 | K24: 0 | L24: 0 | M24: ='08-03-2026'!J79 -> 89658 | N24: 0 | O24: 0
C25: TAHORA | D25: MURTAZA | E25: - | F25: 0 | G25: 0 | H25: =F25-G25 -> 0 | I25: =H25-J25 -> 0 | J25: 0 | K25: 0 | L25: 0 | M25: ='08-03-2026'!J80 -> 17000 | N25: 0 | O25: 0
C26: Total | F26: =SUM(F24:F25) -> 0 | G26: =SUM(G24:G25) -> 0 | H26: =SUM(H24:H25) -> 0 | I26: =SUM(I24:I25) -> 0 | J26: =SUM(J24:J25) -> 0 | K26: =SUM(K24:K25) -> 0 | L26: =SUM(L24:L25) -> 0 | M26: =SUM(M24:M25) -> 106658 | ... O26: =SUM(O24:O25) -> 0
C27: SHAN | D27: KHAWAR | E27: Awais | F27: 55524 | G27: 0 | H27: =F27-G27 -> 55524 | I27: =H27-J27 -> 36927 | J27: 18597 | K27: 0 | L27: 0 | M27: ='08-03-2026'!J67 -> 1432028 | N27: 0 | O27: 71325
C28: SHAN | D28: MURTAZA | E28: - | F28: 0 | G28: 0 | H28: =F28-G28 -> 0 | I28: =H28-J28 -> 0 | J28: 0 | K28: 0 | L28: 0 | M28: ='08-03-2026'!J68 -> 174473 | N28: 0 | O28: 0
C29: SHAN | D29: DANISH | E29: - | F29: 0 | G29: 0 | H29: =F29-G29 -> 0 | I29: =H29-J29 -> 0 | J29: 0 | K29: 0 | L29: 0 | M29: ='08-03-2026'!J69 -> 35126 | N29: 0 | O29: 0
C30: SHAN | D30: ASHRAF | E30: Ayoub | F30: 54430 | G30: 0 | H30: =F30-G30 -> 54430 | I30: =H30-J30 -> 49684 | J30: 4746 | K30: 0 | L30: 0 | M30: ='08-03-2026'!J70 -> 1419313 | N30: 0 | O30: 52780
C31: Total | F31: =SUM(F27:F30) -> 109954 | G31: =SUM(G27:G30) -> 0 | H31: =SUM(H27:H30) -> 109954 | I31: =SUM(I27:I30) -> 86611 | J31: =SUM(J27:J30) -> 23343 | K31: =SUM(K27:K30) -> 0 | L31: =SUM(L27:L30) -> 0 | M31: =SUM(M27:M30) -> 3060940 | ... O31: =SUM(O27:O30) -> 124105
C32: NET TOTAL | F32: =F31+F26+F23+F20+F18+F11 -> 1060021 | G32: =G31+G26+G23+G20+G18+G11 -> 3533 | H32: =H31+H26+H23+H20+H18+H11 -> 1056488 | I32: =I31+I26+I23+I20+I18+I11 -> 759594 | J32: =J31+J26+J23+J20+J18+J11 -> 296894 | K32: =K31+K26+K23+K20+K18+K11 -> 0 | L32: =L31+L26+L23+L20+L18+L11 -> 0 | M32: =M31+M26+M23+M20+M18+M11 -> 13787941 | ... O32: =O31+O26+O23+O20+O18+O11 -> 868672
F33: CBL Cash | G33: =O11+L11+J11-K11 -> 468823
F34: CDM Cash | G34: =O18+L18+J18-K18+O20+L20+J20-K20 -> 549295 | I34: Amount | J34: MCB Onlines | K34: Value | M34: Detail
C35: Onlines | F35: Imported Item Cash | G35: =O23+L23+J23-K23 -> 0
F36: TAHORA | G36: =O26+L26+J26-K26 -> 0
F37: Shan Food's Cash | G37: =O31+L31+J31-K31 -> 147448
F38: Total Cash | G38: =SUM(G33:G37) -> 1165566
H48: Today Credit Closed
H49: COMPANY | I49: ODERBOOKERS | J49: CREDIT AMOUNT
H50: CBL | I50: Danish | J50: =M5-O5-N5-L5+I5 -> 297685 | K50: 297685 | L50: =J50-K50 -> 0
...

Sheet 10-03-2026
C2: 46091
C3: Daily Cash Flow Statement
C4: Companies | D4: Order Bookers | E4: Suppliers | F4: Today Supply | G4: Return Stock | H4: Posting | I4: Credit Posted | J4: Summary Cash | K4: Claim Cleard By Suppliers | L4: Sabqa Payment By Suppliers | M4: Recovery List | N4: Return Stock/Claim Clear By OB | O4: Total Recovery
C5: CBL | D5: Danish | E5: Aqib | F5: 45330 | G5: 0 | H5: =F5-G5 -> 45330 | I5: =H5-J5 -> 12452 | J5: 32878 | K5: 0 | L5: 29714 | M5: ='09-03-2026'!J50 -> 297685 | N5: 0 | O5: 26739
C6: CBL | D6: Danish | E6: Ikram | F6: 49338 | G6: 1766 | H6: =F6-G6 -> 47572 | I6: =H6-J6 -> 26077 | J6: 21495 | K6: 0 | L6: 0 | M6: 0 | N6: 0 | O6: 0
C7: CBL | D7: Danish ws | E7: Ikram | F7: 0 | G7: 0 | H7: =F7-G7 -> 0 | I7: =H7-J7 -> 0 | J7: 0 | K7: 0 | L7: 0 | M7: ='09-03-2026'!J51 -> 3550290 | N7: 0 | O7: 50000
C8: CBL | D8: Murtaza | E8: Aqib | F8: 244376 | G8: 3186 | H8: =F8-G8 -> 241190 | I8: =H8-J8 -> 165023 | J8: 76167 | K8: 0 | L8: 0 | M8: ='09-03-2026'!J52 -> 1468781 | N8: 0 | O8: 50852
C9: CBL | D9: Ali | E9: Ayoub | F9: 108168 | G9: 0 | H9: =F9-G9 -> 108168 | I9: =H9-J9 -> 106607 | J9: 1561 | K9: 0 | L9: 0 | M9: ='09-03-2026'!J53 -> 1033158 | N9: 0 | O9: 94246
C10: CBL | D10: Kashif | E10: Awais | F10: 240217 | G10: 2147 | H10: =F10-G10 -> 238070 | I10: =H10-J10 -> 67871 | J10: 170199 | K10: 0 | L10: 0 | M10: ='09-03-2026'!J54 -> 1294633 | N10: 0 | O10: 68120
C11: CBL | D11: Anas | E11: Saad | F11: 182197 | G11: 1735 | H11: =F11-G11 -> 180462 | I11: =H11-J11 -> 137028 | J11: 43434 | K11: 0 | L11: 0 | M11: ='09-03-2026'!J55 -> 585584 | N11: 0 | O11: 40113
C12: Total | F12: =SUM(F5:F11) -> 869626 | G12: =SUM(G5:G11) -> 8834 | H12: =SUM(H5:H11) -> 860792 | I12: =SUM(I5:I11) -> 515058 | J12: =SUM(J5:J11) -> 345734 | K12: =SUM(K5:K11) -> 0 | L12: =SUM(L5:L11) -> 29714 | M12: =SUM(M5:M11) -> 8230131 | ... O12: =SUM(O5:O11) -> 330070
C13: CDM/TANG | D13: QADEER | E13: Sami | F13: 130277 | G13: 9057 | H13: =F13-G13 -> 121220 | I13: =H13-J13 -> 76364 | J13: 44856 | K13: 0 | L13: 0 | M13: ='09-03-2026'!J59 -> 445718 | N13: 0 | O13: 0
C14: CDM/TANG | D14: SHAHID | E14: Ikram | F14: 34771 | G14: 0 | H14: =F14-G14 -> 34771 | I14: =H14-J14 -> 7684 | J14: 27087 | K14: 0 | L14: 15363 | M14: ='09-03-2026'!J60 -> 1364476 | N14: 0 | O14: 70813
C15: CDM/TANG | D15: SHAHID | E15: Awais | F15: 233453 | G15: 1114 | H15: =F15-G15 -> 232339 | I15: =H15-J15 -> 38696 | J15: 193643 | K15: 92 | L15: 0 | M15: 0 | N15: 0 | O15: 0
C16: CDM/TANG | D16: SHAHID | E16: Saad | F16: 59309 | H16: =F16-G16 -> 59309 | I16: =H16-J16 -> 1876 | J16: 57433 | K16: 0 | L16: 0 | M16: 0 | N16: 0 | O16: 0
C17: CDM/TANG | D17: SHAHID | E17: Sami | F17: 243218 | G17: 0 | H17: =F17-G17 -> 243218 | I17: =H17-J17 -> 243218 | J17: 0
C18: CDM/TANG | D18: DANISH | E18: Ikram | F18: 36571 | G18: 0 | H18: =F18-G18 -> 36571 | I18: =H18-J18 -> 25692 | J18: 10879 | K18: 0 | L18: 0 | M18: ='09-03-2026'!J61 -> 457177 | N18: 0 | O18: 0
C19: CDM/TANG | D19: Kashif | E19: Awais | F19: 0 | G19: 0 | H19: =F19-G19 -> 0 | I19: =H19-J19 -> 0 | J19: 0 | K19: 0 | L19: 0 | M19: 0 | N19: 0 | O19: 0
